*** Starting uWSGI 2.0.18 (64bit) on [Mon Aug 26 00:40:28 2019] ***
compiled with version: 4.2.1 Compatible Apple LLVM 7.0.2 (clang-700.1.81) on 15 May 2019 10:25:14
os: Darwin-18.7.0 Darwin Kernel Version 18.7.0: Thu Jun 20 18:42:21 PDT 2019; root:xnu-4903.270.47~4/RELEASE_X86_64
nodename: joshuaMBP
machine: x86_64
clock source: unix
pcre jit disabled
detected number of CPU cores: 12
current working directory: /Users/jc/Dropbox/workspace/runMES/runMES_1908rc1p5/runMES
writing pidfile to /Users/jc/Dropbox/workspace/runMES/runMES_1908rc1p5/uwsgi-master.pid
detected binary path: /Users/jc/Dropbox/workspace/runMES/runMES_1908rc1p5/bin/uwsgi
chdir() to /Users/jc/Dropbox/workspace/runMES/runMES_1908rc1p5/runMES/
your processes number limit is 1418
your memory page size is 4096 bytes
detected max file descriptor number: 10240
building mime-types dictionary from file /etc/apache2/mime.types...1003 entry found
lock engine: OSX spinlocks
thunder lock: disabled (you can enable it with --thunder-lock)
uWSGI http bound on 0.0.0.0:8000 fd 4
uwsgi socket 0 bound to TCP address 127.0.0.1:63249 (port auto-assigned) fd 3
Python version: 3.6.4 (v3.6.4:d48ecebad5, Dec 18 2017, 21:07:28)  [GCC 4.2.1 (Apple Inc. build 5666) (dot 3)]
Set PythonHome to /Users/jc/Dropbox/workspace/runMES/runMES_1908rc1p5/
*** Python threads support is disabled. You can enable it with --enable-threads ***
Python main interpreter initialized at 0x7fe530805600
your server socket listen backlog is limited to 100 connections
your mercy for graceful operations on workers is 60 seconds
[uwsgi-cron] command "{ sleep 66 && kill -HUP $(cat /Users/jc/Dropbox/workspace/runMES/runMES_1908rc1p5/uwsgi-master.pid) && ls -tp /Users/jc/Dropbox/workspace/runMES/runMES_1908rc1p5/runMES/uwsgi-* | grep -v '/$' | tail -n +7  | xargs -d '\n' -r rm --; } &" registered as cron task
mapped 1117336 bytes (1091 KB) for 10 cores
*** Operational MODE: preforking ***
WSGI app 0 (mountpoint='') ready in 1 seconds on interpreter 0x7fe530805600 pid: 87421 (default app)
*** uWSGI is running in multiple interpreter mode ***
spawned uWSGI master process (pid: 87421)
spawned uWSGI worker 1 (pid: 87425, cores: 1)
spawned uWSGI worker 2 (pid: 87426, cores: 1)
spawned uWSGI worker 3 (pid: 87427, cores: 1)
spawned uWSGI worker 4 (pid: 87428, cores: 1)
spawned uWSGI worker 5 (pid: 87429, cores: 1)
spawned uWSGI worker 6 (pid: 87430, cores: 1)
spawned uWSGI worker 7 (pid: 87431, cores: 1)
spawned uWSGI worker 8 (pid: 87432, cores: 1)
spawned uWSGI worker 9 (pid: 87433, cores: 1)
spawned uWSGI worker 10 (pid: 87434, cores: 1)
spawned uWSGI http 1 (pid: 87435)
subprocess 87422 exited with code 0
Traceback (most recent call last):
  File "/Users/jc/Dropbox/workspace/runMES/runMES_1908rc1p5/lib/python3.6/site-packages/django/core/handlers/exception.py", line 34, in inner
    response = get_response(request)
  File "/Users/jc/Dropbox/workspace/runMES/runMES_1908rc1p5/lib/python3.6/site-packages/django/utils/deprecation.py", line 93, in __call__
    response = self.process_request(request)
  File "/Users/jc/Dropbox/workspace/runMES/runMES_1908rc1p5/lib/python3.6/site-packages/django/middleware/locale.py", line 20, in process_request
    i18n_patterns_used, prefixed_default_language = is_language_prefix_patterns_used(urlconf)
  File "/Users/jc/Dropbox/workspace/runMES/runMES_1908rc1p5/lib/python3.6/site-packages/django/conf/urls/i18n.py", line 31, in is_language_prefix_patterns_used
    for url_pattern in get_resolver(urlconf).url_patterns:
  File "/Users/jc/Dropbox/workspace/runMES/runMES_1908rc1p5/lib/python3.6/site-packages/django/utils/functional.py", line 80, in __get__
    res = instance.__dict__[self.name] = self.func(instance)
  File "/Users/jc/Dropbox/workspace/runMES/runMES_1908rc1p5/lib/python3.6/site-packages/django/urls/resolvers.py", line 579, in url_patterns
    patterns = getattr(self.urlconf_module, "urlpatterns", self.urlconf_module)
  File "/Users/jc/Dropbox/workspace/runMES/runMES_1908rc1p5/lib/python3.6/site-packages/django/utils/functional.py", line 80, in __get__
    res = instance.__dict__[self.name] = self.func(instance)
  File "/Users/jc/Dropbox/workspace/runMES/runMES_1908rc1p5/lib/python3.6/site-packages/django/urls/resolvers.py", line 572, in urlconf_module
    return import_module(self.urlconf_name)
  File "/Users/jc/Dropbox/workspace/runMES/runMES_1908rc1p5/lib/python3.6/importlib/__init__.py", line 126, in import_module
    return _bootstrap._gcd_import(name[level:], package, level)
  File "<frozen importlib._bootstrap>", line 994, in _gcd_import
  File "<frozen importlib._bootstrap>", line 971, in _find_and_load
  File "<frozen importlib._bootstrap>", line 955, in _find_and_load_unlocked
  File "<frozen importlib._bootstrap>", line 665, in _load_unlocked
  File "<frozen importlib._bootstrap_external>", line 678, in exec_module
  File "<frozen importlib._bootstrap>", line 219, in _call_with_frames_removed
  File "./runMES/urls.py", line 18, in <module>
    from runMES import views
  File "./runMES/views.py", line 17, in <module>
    from django.contrib import sett
ImportError: cannot import name 'sett'

During handling of the above exception, another exception occurred:

Traceback (most recent call last):
  File "/Users/jc/Dropbox/workspace/runMES/runMES_1908rc1p5/lib/python3.6/site-packages/django/core/handlers/exception.py", line 34, in inner
    response = get_response(request)
  File "/Users/jc/Dropbox/workspace/runMES/runMES_1908rc1p5/lib/python3.6/site-packages/django/utils/deprecation.py", line 94, in __call__
    response = response or self.get_response(request)
  File "/Users/jc/Dropbox/workspace/runMES/runMES_1908rc1p5/lib/python3.6/site-packages/django/core/handlers/exception.py", line 36, in inner
    response = response_for_exception(request, exc)
  File "/Users/jc/Dropbox/workspace/runMES/runMES_1908rc1p5/lib/python3.6/site-packages/django/core/handlers/exception.py", line 90, in response_for_exception
    response = handle_uncaught_exception(request, get_resolver(get_urlconf()), sys.exc_info())
  File "/Users/jc/Dropbox/workspace/runMES/runMES_1908rc1p5/lib/python3.6/site-packages/django/core/handlers/exception.py", line 128, in handle_uncaught_exception
    callback, param_dict = resolver.resolve_error_handler(500)
  File "/Users/jc/Dropbox/workspace/runMES/runMES_1908rc1p5/lib/python3.6/site-packages/django/urls/resolvers.py", line 592, in resolve_error_handler
    callback = getattr(self.urlconf_module, 'handler%s' % view_type, None)
  File "/Users/jc/Dropbox/workspace/runMES/runMES_1908rc1p5/lib/python3.6/site-packages/django/utils/functional.py", line 80, in __get__
    res = instance.__dict__[self.name] = self.func(instance)
  File "/Users/jc/Dropbox/workspace/runMES/runMES_1908rc1p5/lib/python3.6/site-packages/django/urls/resolvers.py", line 572, in urlconf_module
    return import_module(self.urlconf_name)
  File "/Users/jc/Dropbox/workspace/runMES/runMES_1908rc1p5/lib/python3.6/importlib/__init__.py", line 126, in import_module
    return _bootstrap._gcd_import(name[level:], package, level)
  File "<frozen importlib._bootstrap>", line 994, in _gcd_import
  File "<frozen importlib._bootstrap>", line 971, in _find_and_load
  File "<frozen importlib._bootstrap>", line 955, in _find_and_load_unlocked
  File "<frozen importlib._bootstrap>", line 665, in _load_unlocked
  File "<frozen importlib._bootstrap_external>", line 678, in exec_module
  File "<frozen importlib._bootstrap>", line 219, in _call_with_frames_removed
  File "./runMES/urls.py", line 18, in <module>
    from runMES import views
  File "./runMES/views.py", line 17, in <module>
    from django.contrib import sett
ImportError: cannot import name 'sett'

During handling of the above exception, another exception occurred:

Traceback (most recent call last):
  File "/Users/jc/Dropbox/workspace/runMES/runMES_1908rc1p5/lib/python3.6/site-packages/django/core/handlers/exception.py", line 34, in inner
    response = get_response(request)
  File "/Users/jc/Dropbox/workspace/runMES/runMES_1908rc1p5/lib/python3.6/site-packages/whitenoise/middleware.py", line 49, in __call__
    response = self.get_response(request)
  File "/Users/jc/Dropbox/workspace/runMES/runMES_1908rc1p5/lib/python3.6/site-packages/django/core/handlers/exception.py", line 36, in inner
    response = response_for_exception(request, exc)
  File "/Users/jc/Dropbox/workspace/runMES/runMES_1908rc1p5/lib/python3.6/site-packages/django/core/handlers/exception.py", line 90, in response_for_exception
    response = handle_uncaught_exception(request, get_resolver(get_urlconf()), sys.exc_info())
  File "/Users/jc/Dropbox/workspace/runMES/runMES_1908rc1p5/lib/python3.6/site-packages/django/core/handlers/exception.py", line 128, in handle_uncaught_exception
    callback, param_dict = resolver.resolve_error_handler(500)
  File "/Users/jc/Dropbox/workspace/runMES/runMES_1908rc1p5/lib/python3.6/site-packages/django/urls/resolvers.py", line 592, in resolve_error_handler
    callback = getattr(self.urlconf_module, 'handler%s' % view_type, None)
  File "/Users/jc/Dropbox/workspace/runMES/runMES_1908rc1p5/lib/python3.6/site-packages/django/utils/functional.py", line 80, in __get__
    res = instance.__dict__[self.name] = self.func(instance)
  File "/Users/jc/Dropbox/workspace/runMES/runMES_1908rc1p5/lib/python3.6/site-packages/django/urls/resolvers.py", line 572, in urlconf_module
    return import_module(self.urlconf_name)
  File "/Users/jc/Dropbox/workspace/runMES/runMES_1908rc1p5/lib/python3.6/importlib/__init__.py", line 126, in import_module
    return _bootstrap._gcd_import(name[level:], package, level)
  File "<frozen importlib._bootstrap>", line 994, in _gcd_import
  File "<frozen importlib._bootstrap>", line 971, in _find_and_load
  File "<frozen importlib._bootstrap>", line 955, in _find_and_load_unlocked
  File "<frozen importlib._bootstrap>", line 665, in _load_unlocked
  File "<frozen importlib._bootstrap_external>", line 678, in exec_module
  File "<frozen importlib._bootstrap>", line 219, in _call_with_frames_removed
  File "./runMES/urls.py", line 18, in <module>
    from runMES import views
  File "./runMES/views.py", line 17, in <module>
    from django.contrib import sett
ImportError: cannot import name 'sett'

During handling of the above exception, another exception occurred:

Traceback (most recent call last):
  File "/Users/jc/Dropbox/workspace/runMES/runMES_1908rc1p5/lib/python3.6/site-packages/whitenoise/base.py", line 75, in __call__
    return self.application(environ, start_response)
  File "/Users/jc/Dropbox/workspace/runMES/runMES_1908rc1p5/lib/python3.6/site-packages/django/core/handlers/wsgi.py", line 141, in __call__
    response = self.get_response(request)
  File "/Users/jc/Dropbox/workspace/runMES/runMES_1908rc1p5/lib/python3.6/site-packages/django/core/handlers/base.py", line 75, in get_response
    response = self._middleware_chain(request)
  File "/Users/jc/Dropbox/workspace/runMES/runMES_1908rc1p5/lib/python3.6/site-packages/django/core/handlers/exception.py", line 36, in inner
    response = response_for_exception(request, exc)
  File "/Users/jc/Dropbox/workspace/runMES/runMES_1908rc1p5/lib/python3.6/site-packages/django/core/handlers/exception.py", line 90, in response_for_exception
    response = handle_uncaught_exception(request, get_resolver(get_urlconf()), sys.exc_info())
  File "/Users/jc/Dropbox/workspace/runMES/runMES_1908rc1p5/lib/python3.6/site-packages/django/core/handlers/exception.py", line 128, in handle_uncaught_exception
    callback, param_dict = resolver.resolve_error_handler(500)
  File "/Users/jc/Dropbox/workspace/runMES/runMES_1908rc1p5/lib/python3.6/site-packages/django/urls/resolvers.py", line 592, in resolve_error_handler
    callback = getattr(self.urlconf_module, 'handler%s' % view_type, None)
  File "/Users/jc/Dropbox/workspace/runMES/runMES_1908rc1p5/lib/python3.6/site-packages/django/utils/functional.py", line 80, in __get__
    res = instance.__dict__[self.name] = self.func(instance)
  File "/Users/jc/Dropbox/workspace/runMES/runMES_1908rc1p5/lib/python3.6/site-packages/django/urls/resolvers.py", line 572, in urlconf_module
    return import_module(self.urlconf_name)
  File "/Users/jc/Dropbox/workspace/runMES/runMES_1908rc1p5/lib/python3.6/importlib/__init__.py", line 126, in import_module
    return _bootstrap._gcd_import(name[level:], package, level)
  File "<frozen importlib._bootstrap>", line 994, in _gcd_import
  File "<frozen importlib._bootstrap>", line 971, in _find_and_load
  File "<frozen importlib._bootstrap>", line 955, in _find_and_load_unlocked
  File "<frozen importlib._bootstrap>", line 665, in _load_unlocked
  File "<frozen importlib._bootstrap_external>", line 678, in exec_module
  File "<frozen importlib._bootstrap>", line 219, in _call_with_frames_removed
  File "./runMES/urls.py", line 18, in <module>
    from runMES import views
  File "./runMES/views.py", line 17, in <module>
    from django.contrib import sett
ImportError: cannot import name 'sett'
[pid: 87427|app: 0|req: 1/236] 127.0.0.1 () {40 vars in 1641 bytes} [Mon Aug 26 00:53:25 2019] GET /CFM/cfm_ajax/?_=1566751233926 => generated 0 bytes in 144 msecs (HTTP/1.1 500) 0 headers in 0 bytes (0 switches on core 0)
Traceback (most recent call last):
  File "/Users/jc/Dropbox/workspace/runMES/runMES_1908rc1p5/lib/python3.6/site-packages/django/core/handlers/exception.py", line 34, in inner
    response = get_response(request)
  File "/Users/jc/Dropbox/workspace/runMES/runMES_1908rc1p5/lib/python3.6/site-packages/django/utils/deprecation.py", line 93, in __call__
    response = self.process_request(request)
  File "/Users/jc/Dropbox/workspace/runMES/runMES_1908rc1p5/lib/python3.6/site-packages/django/middleware/locale.py", line 20, in process_request
    i18n_patterns_used, prefixed_default_language = is_language_prefix_patterns_used(urlconf)
  File "/Users/jc/Dropbox/workspace/runMES/runMES_1908rc1p5/lib/python3.6/site-packages/django/conf/urls/i18n.py", line 31, in is_language_prefix_patterns_used
    for url_pattern in get_resolver(urlconf).url_patterns:
  File "/Users/jc/Dropbox/workspace/runMES/runMES_1908rc1p5/lib/python3.6/site-packages/django/utils/functional.py", line 80, in __get__
    res = instance.__dict__[self.name] = self.func(instance)
  File "/Users/jc/Dropbox/workspace/runMES/runMES_1908rc1p5/lib/python3.6/site-packages/django/urls/resolvers.py", line 579, in url_patterns
    patterns = getattr(self.urlconf_module, "urlpatterns", self.urlconf_module)
  File "/Users/jc/Dropbox/workspace/runMES/runMES_1908rc1p5/lib/python3.6/site-packages/django/utils/functional.py", line 80, in __get__
    res = instance.__dict__[self.name] = self.func(instance)
  File "/Users/jc/Dropbox/workspace/runMES/runMES_1908rc1p5/lib/python3.6/site-packages/django/urls/resolvers.py", line 572, in urlconf_module
    return import_module(self.urlconf_name)
  File "/Users/jc/Dropbox/workspace/runMES/runMES_1908rc1p5/lib/python3.6/importlib/__init__.py", line 126, in import_module
    return _bootstrap._gcd_import(name[level:], package, level)
  File "<frozen importlib._bootstrap>", line 994, in _gcd_import
  File "<frozen importlib._bootstrap>", line 971, in _find_and_load
  File "<frozen importlib._bootstrap>", line 955, in _find_and_load_unlocked
  File "<frozen importlib._bootstrap>", line 665, in _load_unlocked
  File "<frozen importlib._bootstrap_external>", line 678, in exec_module
  File "<frozen importlib._bootstrap>", line 219, in _call_with_frames_removed
  File "./runMES/urls.py", line 18, in <module>
    from runMES import views
  File "./runMES/views.py", line 17, in <module>
    from django.contrib import sett
ImportError: cannot import name 'sett'

During handling of the above exception, another exception occurred:

Traceback (most recent call last):
  File "/Users/jc/Dropbox/workspace/runMES/runMES_1908rc1p5/lib/python3.6/site-packages/django/core/handlers/exception.py", line 34, in inner
    response = get_response(request)
  File "/Users/jc/Dropbox/workspace/runMES/runMES_1908rc1p5/lib/python3.6/site-packages/django/utils/deprecation.py", line 94, in __call__
    response = response or self.get_response(request)
  File "/Users/jc/Dropbox/workspace/runMES/runMES_1908rc1p5/lib/python3.6/site-packages/django/core/handlers/exception.py", line 36, in inner
    response = response_for_exception(request, exc)
  File "/Users/jc/Dropbox/workspace/runMES/runMES_1908rc1p5/lib/python3.6/site-packages/django/core/handlers/exception.py", line 90, in response_for_exception
    response = handle_uncaught_exception(request, get_resolver(get_urlconf()), sys.exc_info())
  File "/Users/jc/Dropbox/workspace/runMES/runMES_1908rc1p5/lib/python3.6/site-packages/django/core/handlers/exception.py", line 128, in handle_uncaught_exception
    callback, param_dict = resolver.resolve_error_handler(500)
  File "/Users/jc/Dropbox/workspace/runMES/runMES_1908rc1p5/lib/python3.6/site-packages/django/urls/resolvers.py", line 592, in resolve_error_handler
    callback = getattr(self.urlconf_module, 'handler%s' % view_type, None)
  File "/Users/jc/Dropbox/workspace/runMES/runMES_1908rc1p5/lib/python3.6/site-packages/django/utils/functional.py", line 80, in __get__
    res = instance.__dict__[self.name] = self.func(instance)
  File "/Users/jc/Dropbox/workspace/runMES/runMES_1908rc1p5/lib/python3.6/site-packages/django/urls/resolvers.py", line 572, in urlconf_module
    return import_module(self.urlconf_name)
  File "/Users/jc/Dropbox/workspace/runMES/runMES_1908rc1p5/lib/python3.6/importlib/__init__.py", line 126, in import_module
    return _bootstrap._gcd_import(name[level:], package, level)
  File "<frozen importlib._bootstrap>", line 994, in _gcd_import
  File "<frozen importlib._bootstrap>", line 971, in _find_and_load
  File "<frozen importlib._bootstrap>", line 955, in _find_and_load_unlocked
  File "<frozen importlib._bootstrap>", line 665, in _load_unlocked
  File "<frozen importlib._bootstrap_external>", line 678, in exec_module
  File "<frozen importlib._bootstrap>", line 219, in _call_with_frames_removed
  File "./runMES/urls.py", line 18, in <module>
    from runMES import views
  File "./runMES/views.py", line 17, in <module>
    from django.contrib import sett
ImportError: cannot import name 'sett'

During handling of the above exception, another exception occurred:

Traceback (most recent call last):
  File "/Users/jc/Dropbox/workspace/runMES/runMES_1908rc1p5/lib/python3.6/site-packages/django/core/handlers/exception.py", line 34, in inner
    response = get_response(request)
  File "/Users/jc/Dropbox/workspace/runMES/runMES_1908rc1p5/lib/python3.6/site-packages/whitenoise/middleware.py", line 49, in __call__
    response = self.get_response(request)
  File "/Users/jc/Dropbox/workspace/runMES/runMES_1908rc1p5/lib/python3.6/site-packages/django/core/handlers/exception.py", line 36, in inner
    response = response_for_exception(request, exc)
  File "/Users/jc/Dropbox/workspace/runMES/runMES_1908rc1p5/lib/python3.6/site-packages/django/core/handlers/exception.py", line 90, in response_for_exception
    response = handle_uncaught_exception(request, get_resolver(get_urlconf()), sys.exc_info())
  File "/Users/jc/Dropbox/workspace/runMES/runMES_1908rc1p5/lib/python3.6/site-packages/django/core/handlers/exception.py", line 128, in handle_uncaught_exception
    callback, param_dict = resolver.resolve_error_handler(500)
  File "/Users/jc/Dropbox/workspace/runMES/runMES_1908rc1p5/lib/python3.6/site-packages/django/urls/resolvers.py", line 592, in resolve_error_handler
    callback = getattr(self.urlconf_module, 'handler%s' % view_type, None)
  File "/Users/jc/Dropbox/workspace/runMES/runMES_1908rc1p5/lib/python3.6/site-packages/django/utils/functional.py", line 80, in __get__
    res = instance.__dict__[self.name] = self.func(instance)
  File "/Users/jc/Dropbox/workspace/runMES/runMES_1908rc1p5/lib/python3.6/site-packages/django/urls/resolvers.py", line 572, in urlconf_module
    return import_module(self.urlconf_name)
  File "/Users/jc/Dropbox/workspace/runMES/runMES_1908rc1p5/lib/python3.6/importlib/__init__.py", line 126, in import_module
    return _bootstrap._gcd_import(name[level:], package, level)
  File "<frozen importlib._bootstrap>", line 994, in _gcd_import
  File "<frozen importlib._bootstrap>", line 971, in _find_and_load
  File "<frozen importlib._bootstrap>", line 955, in _find_and_load_unlocked
  File "<frozen importlib._bootstrap>", line 665, in _load_unlocked
  File "<frozen importlib._bootstrap_external>", line 678, in exec_module
  File "<frozen importlib._bootstrap>", line 219, in _call_with_frames_removed
  File "./runMES/urls.py", line 18, in <module>
    from runMES import views
  File "./runMES/views.py", line 17, in <module>
    from django.contrib import sett
ImportError: cannot import name 'sett'

During handling of the above exception, another exception occurred:

Traceback (most recent call last):
  File "/Users/jc/Dropbox/workspace/runMES/runMES_1908rc1p5/lib/python3.6/site-packages/whitenoise/base.py", line 75, in __call__
    return self.application(environ, start_response)
  File "/Users/jc/Dropbox/workspace/runMES/runMES_1908rc1p5/lib/python3.6/site-packages/django/core/handlers/wsgi.py", line 141, in __call__
    response = self.get_response(request)
  File "/Users/jc/Dropbox/workspace/runMES/runMES_1908rc1p5/lib/python3.6/site-packages/django/core/handlers/base.py", line 75, in get_response
    response = self._middleware_chain(request)
  File "/Users/jc/Dropbox/workspace/runMES/runMES_1908rc1p5/lib/python3.6/site-packages/django/core/handlers/exception.py", line 36, in inner
    response = response_for_exception(request, exc)
  File "/Users/jc/Dropbox/workspace/runMES/runMES_1908rc1p5/lib/python3.6/site-packages/django/core/handlers/exception.py", line 90, in response_for_exception
    response = handle_uncaught_exception(request, get_resolver(get_urlconf()), sys.exc_info())
  File "/Users/jc/Dropbox/workspace/runMES/runMES_1908rc1p5/lib/python3.6/site-packages/django/core/handlers/exception.py", line 128, in handle_uncaught_exception
    callback, param_dict = resolver.resolve_error_handler(500)
  File "/Users/jc/Dropbox/workspace/runMES/runMES_1908rc1p5/lib/python3.6/site-packages/django/urls/resolvers.py", line 592, in resolve_error_handler
    callback = getattr(self.urlconf_module, 'handler%s' % view_type, None)
  File "/Users/jc/Dropbox/workspace/runMES/runMES_1908rc1p5/lib/python3.6/site-packages/django/utils/functional.py", line 80, in __get__
    res = instance.__dict__[self.name] = self.func(instance)
  File "/Users/jc/Dropbox/workspace/runMES/runMES_1908rc1p5/lib/python3.6/site-packages/django/urls/resolvers.py", line 572, in urlconf_module
    return import_module(self.urlconf_name)
  File "/Users/jc/Dropbox/workspace/runMES/runMES_1908rc1p5/lib/python3.6/importlib/__init__.py", line 126, in import_module
    return _bootstrap._gcd_import(name[level:], package, level)
  File "<frozen importlib._bootstrap>", line 994, in _gcd_import
  File "<frozen importlib._bootstrap>", line 971, in _find_and_load
  File "<frozen importlib._bootstrap>", line 955, in _find_and_load_unlocked
  File "<frozen importlib._bootstrap>", line 665, in _load_unlocked
  File "<frozen importlib._bootstrap_external>", line 678, in exec_module
  File "<frozen importlib._bootstrap>", line 219, in _call_with_frames_removed
  File "./runMES/urls.py", line 18, in <module>
    from runMES import views
  File "./runMES/views.py", line 17, in <module>
    from django.contrib import sett
ImportError: cannot import name 'sett'
[pid: 87427|app: 0|req: 2/309] 127.0.0.1 () {40 vars in 1641 bytes} [Mon Aug 26 00:59:25 2019] GET /CFM/cfm_ajax/?_=1566751233998 => generated 0 bytes in 10 msecs (HTTP/1.1 500) 0 headers in 0 bytes (0 switches on core 0)
Traceback (most recent call last):
  File "/Users/jc/Dropbox/workspace/runMES/runMES_1908rc1p5/lib/python3.6/site-packages/django/core/handlers/exception.py", line 34, in inner
    response = get_response(request)
  File "/Users/jc/Dropbox/workspace/runMES/runMES_1908rc1p5/lib/python3.6/site-packages/django/utils/deprecation.py", line 93, in __call__
    response = self.process_request(request)
  File "/Users/jc/Dropbox/workspace/runMES/runMES_1908rc1p5/lib/python3.6/site-packages/django/middleware/locale.py", line 20, in process_request
    i18n_patterns_used, prefixed_default_language = is_language_prefix_patterns_used(urlconf)
  File "/Users/jc/Dropbox/workspace/runMES/runMES_1908rc1p5/lib/python3.6/site-packages/django/conf/urls/i18n.py", line 31, in is_language_prefix_patterns_used
    for url_pattern in get_resolver(urlconf).url_patterns:
  File "/Users/jc/Dropbox/workspace/runMES/runMES_1908rc1p5/lib/python3.6/site-packages/django/utils/functional.py", line 80, in __get__
    res = instance.__dict__[self.name] = self.func(instance)
  File "/Users/jc/Dropbox/workspace/runMES/runMES_1908rc1p5/lib/python3.6/site-packages/django/urls/resolvers.py", line 579, in url_patterns
    patterns = getattr(self.urlconf_module, "urlpatterns", self.urlconf_module)
  File "/Users/jc/Dropbox/workspace/runMES/runMES_1908rc1p5/lib/python3.6/site-packages/django/utils/functional.py", line 80, in __get__
    res = instance.__dict__[self.name] = self.func(instance)
  File "/Users/jc/Dropbox/workspace/runMES/runMES_1908rc1p5/lib/python3.6/site-packages/django/urls/resolvers.py", line 572, in urlconf_module
    return import_module(self.urlconf_name)
  File "/Users/jc/Dropbox/workspace/runMES/runMES_1908rc1p5/lib/python3.6/importlib/__init__.py", line 126, in import_module
    return _bootstrap._gcd_import(name[level:], package, level)
  File "<frozen importlib._bootstrap>", line 994, in _gcd_import
  File "<frozen importlib._bootstrap>", line 971, in _find_and_load
  File "<frozen importlib._bootstrap>", line 955, in _find_and_load_unlocked
  File "<frozen importlib._bootstrap>", line 665, in _load_unlocked
  File "<frozen importlib._bootstrap_external>", line 678, in exec_module
  File "<frozen importlib._bootstrap>", line 219, in _call_with_frames_removed
  File "./runMES/urls.py", line 18, in <module>
    from runMES import views
  File "./runMES/views.py", line 17, in <module>
    from django.contrib import sett
ImportError: cannot import name 'sett'

During handling of the above exception, another exception occurred:

Traceback (most recent call last):
  File "/Users/jc/Dropbox/workspace/runMES/runMES_1908rc1p5/lib/python3.6/site-packages/django/core/handlers/exception.py", line 34, in inner
    response = get_response(request)
  File "/Users/jc/Dropbox/workspace/runMES/runMES_1908rc1p5/lib/python3.6/site-packages/django/utils/deprecation.py", line 94, in __call__
    response = response or self.get_response(request)
  File "/Users/jc/Dropbox/workspace/runMES/runMES_1908rc1p5/lib/python3.6/site-packages/django/core/handlers/exception.py", line 36, in inner
    response = response_for_exception(request, exc)
  File "/Users/jc/Dropbox/workspace/runMES/runMES_1908rc1p5/lib/python3.6/site-packages/django/core/handlers/exception.py", line 90, in response_for_exception
    response = handle_uncaught_exception(request, get_resolver(get_urlconf()), sys.exc_info())
  File "/Users/jc/Dropbox/workspace/runMES/runMES_1908rc1p5/lib/python3.6/site-packages/django/core/handlers/exception.py", line 128, in handle_uncaught_exception
    callback, param_dict = resolver.resolve_error_handler(500)
  File "/Users/jc/Dropbox/workspace/runMES/runMES_1908rc1p5/lib/python3.6/site-packages/django/urls/resolvers.py", line 592, in resolve_error_handler
    callback = getattr(self.urlconf_module, 'handler%s' % view_type, None)
  File "/Users/jc/Dropbox/workspace/runMES/runMES_1908rc1p5/lib/python3.6/site-packages/django/utils/functional.py", line 80, in __get__
    res = instance.__dict__[self.name] = self.func(instance)
  File "/Users/jc/Dropbox/workspace/runMES/runMES_1908rc1p5/lib/python3.6/site-packages/django/urls/resolvers.py", line 572, in urlconf_module
    return import_module(self.urlconf_name)
  File "/Users/jc/Dropbox/workspace/runMES/runMES_1908rc1p5/lib/python3.6/importlib/__init__.py", line 126, in import_module
    return _bootstrap._gcd_import(name[level:], package, level)
  File "<frozen importlib._bootstrap>", line 994, in _gcd_import
  File "<frozen importlib._bootstrap>", line 971, in _find_and_load
  File "<frozen importlib._bootstrap>", line 955, in _find_and_load_unlocked
  File "<frozen importlib._bootstrap>", line 665, in _load_unlocked
  File "<frozen importlib._bootstrap_external>", line 678, in exec_module
  File "<frozen importlib._bootstrap>", line 219, in _call_with_frames_removed
  File "./runMES/urls.py", line 18, in <module>
    from runMES import views
  File "./runMES/views.py", line 17, in <module>
    from django.contrib import sett
ImportError: cannot import name 'sett'

During handling of the above exception, another exception occurred:

Traceback (most recent call last):
  File "/Users/jc/Dropbox/workspace/runMES/runMES_1908rc1p5/lib/python3.6/site-packages/django/core/handlers/exception.py", line 34, in inner
    response = get_response(request)
  File "/Users/jc/Dropbox/workspace/runMES/runMES_1908rc1p5/lib/python3.6/site-packages/whitenoise/middleware.py", line 49, in __call__
    response = self.get_response(request)
  File "/Users/jc/Dropbox/workspace/runMES/runMES_1908rc1p5/lib/python3.6/site-packages/django/core/handlers/exception.py", line 36, in inner
    response = response_for_exception(request, exc)
  File "/Users/jc/Dropbox/workspace/runMES/runMES_1908rc1p5/lib/python3.6/site-packages/django/core/handlers/exception.py", line 90, in response_for_exception
    response = handle_uncaught_exception(request, get_resolver(get_urlconf()), sys.exc_info())
  File "/Users/jc/Dropbox/workspace/runMES/runMES_1908rc1p5/lib/python3.6/site-packages/django/core/handlers/exception.py", line 128, in handle_uncaught_exception
    callback, param_dict = resolver.resolve_error_handler(500)
  File "/Users/jc/Dropbox/workspace/runMES/runMES_1908rc1p5/lib/python3.6/site-packages/django/urls/resolvers.py", line 592, in resolve_error_handler
    callback = getattr(self.urlconf_module, 'handler%s' % view_type, None)
  File "/Users/jc/Dropbox/workspace/runMES/runMES_1908rc1p5/lib/python3.6/site-packages/django/utils/functional.py", line 80, in __get__
    res = instance.__dict__[self.name] = self.func(instance)
  File "/Users/jc/Dropbox/workspace/runMES/runMES_1908rc1p5/lib/python3.6/site-packages/django/urls/resolvers.py", line 572, in urlconf_module
    return import_module(self.urlconf_name)
  File "/Users/jc/Dropbox/workspace/runMES/runMES_1908rc1p5/lib/python3.6/importlib/__init__.py", line 126, in import_module
    return _bootstrap._gcd_import(name[level:], package, level)
  File "<frozen importlib._bootstrap>", line 994, in _gcd_import
  File "<frozen importlib._bootstrap>", line 971, in _find_and_load
  File "<frozen importlib._bootstrap>", line 955, in _find_and_load_unlocked
  File "<frozen importlib._bootstrap>", line 665, in _load_unlocked
  File "<frozen importlib._bootstrap_external>", line 678, in exec_module
  File "<frozen importlib._bootstrap>", line 219, in _call_with_frames_removed
  File "./runMES/urls.py", line 18, in <module>
    from runMES import views
  File "./runMES/views.py", line 17, in <module>
    from django.contrib import sett
ImportError: cannot import name 'sett'

During handling of the above exception, another exception occurred:

Traceback (most recent call last):
  File "/Users/jc/Dropbox/workspace/runMES/runMES_1908rc1p5/lib/python3.6/site-packages/whitenoise/base.py", line 75, in __call__
    return self.application(environ, start_response)
  File "/Users/jc/Dropbox/workspace/runMES/runMES_1908rc1p5/lib/python3.6/site-packages/django/core/handlers/wsgi.py", line 141, in __call__
    response = self.get_response(request)
  File "/Users/jc/Dropbox/workspace/runMES/runMES_1908rc1p5/lib/python3.6/site-packages/django/core/handlers/base.py", line 75, in get_response
    response = self._middleware_chain(request)
  File "/Users/jc/Dropbox/workspace/runMES/runMES_1908rc1p5/lib/python3.6/site-packages/django/core/handlers/exception.py", line 36, in inner
    response = response_for_exception(request, exc)
  File "/Users/jc/Dropbox/workspace/runMES/runMES_1908rc1p5/lib/python3.6/site-packages/django/core/handlers/exception.py", line 90, in response_for_exception
    response = handle_uncaught_exception(request, get_resolver(get_urlconf()), sys.exc_info())
  File "/Users/jc/Dropbox/workspace/runMES/runMES_1908rc1p5/lib/python3.6/site-packages/django/core/handlers/exception.py", line 128, in handle_uncaught_exception
    callback, param_dict = resolver.resolve_error_handler(500)
  File "/Users/jc/Dropbox/workspace/runMES/runMES_1908rc1p5/lib/python3.6/site-packages/django/urls/resolvers.py", line 592, in resolve_error_handler
    callback = getattr(self.urlconf_module, 'handler%s' % view_type, None)
  File "/Users/jc/Dropbox/workspace/runMES/runMES_1908rc1p5/lib/python3.6/site-packages/django/utils/functional.py", line 80, in __get__
    res = instance.__dict__[self.name] = self.func(instance)
  File "/Users/jc/Dropbox/workspace/runMES/runMES_1908rc1p5/lib/python3.6/site-packages/django/urls/resolvers.py", line 572, in urlconf_module
    return import_module(self.urlconf_name)
  File "/Users/jc/Dropbox/workspace/runMES/runMES_1908rc1p5/lib/python3.6/importlib/__init__.py", line 126, in import_module
    return _bootstrap._gcd_import(name[level:], package, level)
  File "<frozen importlib._bootstrap>", line 994, in _gcd_import
  File "<frozen importlib._bootstrap>", line 971, in _find_and_load
  File "<frozen importlib._bootstrap>", line 955, in _find_and_load_unlocked
  File "<frozen importlib._bootstrap>", line 665, in _load_unlocked
  File "<frozen importlib._bootstrap_external>", line 678, in exec_module
  File "<frozen importlib._bootstrap>", line 219, in _call_with_frames_removed
  File "./runMES/urls.py", line 18, in <module>
    from runMES import views
  File "./runMES/views.py", line 17, in <module>
    from django.contrib import sett
ImportError: cannot import name 'sett'
[pid: 87426|app: 0|req: 1/342] 127.0.0.1 () {40 vars in 1641 bytes} [Mon Aug 26 01:02:05 2019] GET /CFM/cfm_ajax/?_=1566751234030 => generated 0 bytes in 56 msecs (HTTP/1.1 500) 0 headers in 0 bytes (0 switches on core 0)
Mon Aug 26 03:23:00 2019 - [uwsgi-cron] running "{ sleep 66 && kill -HUP $(cat /Users/jc/Dropbox/workspace/runMES/runMES_1908rc1p5/uwsgi-master.pid) && ls -tp /Users/jc/Dropbox/workspace/runMES/runMES_1908rc1p5/runMES/uwsgi-* | grep -v '/$' | tail -n +7  | xargs -d '\n' -r rm --; } &" (pid 91603)
[uwsgi-cron] command "{ sleep 66 && kill -HUP $(cat /Users/jc/Dropbox/workspace/runMES/runMES_1908rc1p5/uwsgi-master.pid) && ls -tp /Users/jc/Dropbox/workspace/runMES/runMES_1908rc1p5/runMES/uwsgi-* | grep -v '/$' | tail -n +7  | xargs -d '\n' -r rm --; } &" running with pid 91603 exited after 1 second(s)
gateway "uWSGI http 1" has been buried (pid: 87435)
...gracefully killing workers...
Gracefully killing worker 3 (pid: 87427)...
Gracefully killing worker 5 (pid: 87429)...
Gracefully killing worker 4 (pid: 87428)...
Gracefully killing worker 6 (pid: 87430)...
Gracefully killing worker 1 (pid: 87425)...
Gracefully killing worker 7 (pid: 87431)...
Gracefully killing worker 9 (pid: 87433)...
Gracefully killing worker 8 (pid: 87432)...
Gracefully killing worker 2 (pid: 87426)...
Gracefully killing worker 10 (pid: 87434)...
xargs: illegal option -- d
usage: xargs [-0opt] [-E eofstr] [-I replstr [-R replacements]] [-J replstr]
             [-L number] [-n number [-x]] [-P maxprocs] [-s size]
             [utility [argument ...]]
worker 10 buried after 1 seconds
worker 9 buried after 1 seconds
worker 8 buried after 1 seconds
worker 7 buried after 1 seconds
worker 6 buried after 1 seconds
worker 5 buried after 1 seconds
worker 4 buried after 1 seconds
worker 3 buried after 1 seconds
worker 2 buried after 1 seconds
worker 1 buried after 1 seconds
binary reloading uWSGI...
chdir() to /Users/jc/Dropbox/workspace/runMES/runMES_1908rc1p5/runMES
closing all non-uwsgi socket fds > 2 (max_fd = 10240)...
found fd 3 mapped to socket 0 (127.0.0.1:63249)
running /Users/jc/Dropbox/workspace/runMES/runMES_1908rc1p5/bin/uwsgi
[uWSGI] getting INI configuration from ./uwsgi.ini
[uwsgi-static] added check for /Users/jc/Dropbox/workspace/runMES/runMES_1908rc1p5/runMES/static
*** Starting uWSGI 2.0.18 (64bit) on [Mon Aug 26 03:24:07 2019] ***
compiled with version: 4.2.1 Compatible Apple LLVM 7.0.2 (clang-700.1.81) on 15 May 2019 10:25:14
os: Darwin-18.7.0 Darwin Kernel Version 18.7.0: Thu Jun 20 18:42:21 PDT 2019; root:xnu-4903.270.47~4/RELEASE_X86_64
nodename: joshuaMBP
machine: x86_64
clock source: unix
pcre jit disabled
detected number of CPU cores: 12
current working directory: /Users/jc/Dropbox/workspace/runMES/runMES_1908rc1p5/runMES
detected binary path: /Users/jc/Dropbox/workspace/runMES/runMES_1908rc1p5/bin/uwsgi
chdir() to /Users/jc/Dropbox/workspace/runMES/runMES_1908rc1p5/runMES/
your processes number limit is 1418
your memory page size is 4096 bytes
detected max file descriptor number: 10240
building mime-types dictionary from file /etc/apache2/mime.types...1003 entry found
lock engine: OSX spinlocks
thunder lock: disabled (you can enable it with --thunder-lock)
uWSGI http bound on 0.0.0.0:8000 fd 5
uwsgi socket 0 bound to TCP address 127.0.0.1:59729 (port auto-assigned) fd 4
Python version: 3.6.4 (v3.6.4:d48ecebad5, Dec 18 2017, 21:07:28)  [GCC 4.2.1 (Apple Inc. build 5666) (dot 3)]
Set PythonHome to /Users/jc/Dropbox/workspace/runMES/runMES_1908rc1p5/
*** Python threads support is disabled. You can enable it with --enable-threads ***
Python main interpreter initialized at 0x7ffbc6806200
your server socket listen backlog is limited to 100 connections
your mercy for graceful operations on workers is 60 seconds
[uwsgi-cron] command "{ sleep 66 && kill -HUP $(cat /Users/jc/Dropbox/workspace/runMES/runMES_1908rc1p5/uwsgi-master.pid) && ls -tp /Users/jc/Dropbox/workspace/runMES/runMES_1908rc1p5/runMES/uwsgi-* | grep -v '/$' | tail -n +7  | xargs -d '\n' -r rm --; } &" registered as cron task
mapped 1117336 bytes (1091 KB) for 10 cores
*** Operational MODE: preforking ***
WSGI app 0 (mountpoint='') ready in 1 seconds on interpreter 0x7ffbc6806200 pid: 87421 (default app)
*** uWSGI is running in multiple interpreter mode ***
gracefully (RE)spawned uWSGI master process (pid: 87421)
spawned uWSGI worker 1 (pid: 91638, cores: 1)
spawned uWSGI worker 2 (pid: 91639, cores: 1)
spawned uWSGI worker 3 (pid: 91640, cores: 1)
spawned uWSGI worker 4 (pid: 91641, cores: 1)
spawned uWSGI worker 5 (pid: 91642, cores: 1)
spawned uWSGI worker 6 (pid: 91643, cores: 1)
spawned uWSGI worker 7 (pid: 91644, cores: 1)
spawned uWSGI worker 8 (pid: 91645, cores: 1)
spawned uWSGI worker 9 (pid: 91646, cores: 1)
spawned uWSGI worker 10 (pid: 91647, cores: 1)
spawned uWSGI http 1 (pid: 91648)
subprocess 91637 exited with code 0
